<?xml version="1.0" encoding="utf-8" ?>
<!-- This URDF was automatically created by SolidWorks to URDF Exporter! Originally created by Stephen Brawner (brawner@gmail.com) 
     Commit Version: 1.6.0-4-g7f85cfe  Build Version: 1.6.7995.38578
     For more information, please see http://wiki.ros.org/sw_urdf_exporter -->
<robot name="project_model">
    <link name="world" />
    <joint name="base_to_world" type="fixed">
        <parent link="world" />
        <child link="base_link" />
        <origin xyz="0 0 0.2" rpy="0 0 0" />
    </joint>
    <link name="base_link">
    <inertial>
      <origin
        xyz="-0.41716 -0.22524 -0.062655"
        rpy="0 0 0" />
      <mass
        value="30.184" />
      <inertia
        ixx="0.50269"
        ixy="6.6303E-18"
        ixz="-5.6208E-18"
        iyy="0.50269"
        iyz="2.4498E-17"
        izz="0.74044" />
    </inertial>
    <visual>
      <origin
        xyz="0 0 0"
        rpy="0 0 0" />
      <geometry>
        <mesh
          filename="package://project_model/meshes/base_link.STL" />
      </geometry>
      <material
        name="">
        <color
          rgba="0.79216 0.81961 0.93333 1" />
      </material>
    </visual>
    <collision>
      <origin
        xyz="0 0 0"
        rpy="0 0 0" />
      <geometry>
        <mesh
          filename="package://project_model/meshes/base_link.STL" />
      </geometry>
    </collision>
    </link>
    <link name="Link1">
         <inertial>
            <origin
                xyz="0.079357 -0.0012459 0.22046"
                rpy="0 0 0" />
            <mass
                value="85.657" />
            <inertia
                ixx="1.5469"
                ixy="-0.045685"
                ixz="-0.35476"
                iyy="6.739"
                iyz="0.0039495"
                izz="6.7771" />
        </inertial>
        <visual>
            <origin
                xyz="0 0 0"
                rpy="0 0 0" />
            <geometry>
                <mesh
                filename="package://project_model/meshes/Link1.STL" />
            </geometry>
            <material
                name="">
                <color
                rgba="0.79216 0.81961 0.93333 1" />
            </material>
        </visual>
        <collision>
            <origin
                xyz="0 0 0"
                rpy="0 0 0" />
            <geometry>
                <mesh
                filename="package://project_model/meshes/Link1.STL" />
            </geometry>
        </collision>
    </link>
    <link name="Link2">
        <inertial>
            <origin
                xyz="-0.594272331620716 7.00473512527111E-09 0.262790080771701"
                rpy="0 0 0" />
            <mass
                value="51.8329784346567" />
            <inertia
                ixx="0.355230135223329"
                ixy="4.79417319732001E-09"
                ixz="0.211286603259331"
                iyy="8.51616761981559"
                iyz="3.19852841073906E-09"
                izz="8.45194961332558" />
       </inertial>
        <visual>
            <origin
                xyz="0 0 0"
                rpy="0 0 0" />
            <geometry>
                <mesh
                filename="package://project_model/meshes/Link2.STL" />
            </geometry>
            <material
                name="">
                <color
                rgba="0.79216 0.81961 0.93333 1" />
            </material>
        </visual>
        <collision>
            <origin
                xyz="0 0 0"
                rpy="0 0 0" />
            <geometry>
                <mesh
                filename="package://project_model/meshes/Link2.STL" />
            </geometry>
        </collision>
    </link>
    <link name="Link3">
        <inertial>
            <origin
                xyz="-0.44 -0.015319 0.045267"
                rpy="0 0 0" />
            <mass
                value="27.633" />
            <inertia
                ixx="0.10572"
                ixy="-0.13306"
                ixz="-0.0084199"
                iyy="3.8856"
                iyz="-0.00029341"
                izz="3.8991" />
        </inertial>
        <visual>
            <origin
                xyz="0 0 0"
                rpy="0 0 0" />
            <geometry>
                <mesh filename="package://project_model/meshes/Link3_3.STL" />
            </geometry>
            <material name="">
                <color rgba="0.792156862745098 0.819607843137255 0.933333333333333 1" />
            </material>
        </visual>
        <collision>
            <origin xyz="0 0 0" rpy="0 0 0" />
            <geometry>
                <mesh filename="package://project_model/meshes/Link3_3.STL" />
            </geometry>
        </collision>
    </link>
    <link name="Link4">
        <inertial>
            <origin
                xyz="0.12731 4.4464E-07 1.0846E-06"
                rpy="0 0 0" />
            <mass
                value="1.7447" />
            <inertia
                ixx="0.0019413"
                ixy="-5.5825E-07"
                ixz="-8.8735E-07"
                iyy="0.0093006"
                iyz="1.4302E-06"
                izz="0.0093021" />
        </inertial>
        <visual>
            <origin
                xyz="0 0 0"
                rpy="0 0 0" />
            <geometry>
                <mesh filename="package://project_model/meshes/Link4.STL" />
            </geometry>
            <material name="">
                <color rgba="0.792156862745098 0.819607843137255 0.933333333333333 1" />
            </material>
        </visual>
        <collision>
            <origin xyz="0 0 0" rpy="0 0 0" />
            <geometry>
                <mesh filename="package://project_model/meshes/Link4.STL" />
            </geometry>
        </collision>
    </link>
    <link
        name="Vakuumgreifer">
        <inertial>
        <origin
            xyz="-3.3311E-05 -2.4035E-05 0.09656"
            rpy="0 0 0" />
        <mass
            value="0.87056" />
        <inertia
            ixx="0.003077"
            ixy="2.0868E-06"
            ixz="7.0458E-07"
            iyy="0.0019201"
            iyz="-1.2039E-06"
            izz="0.0042488" />
        </inertial>
        <visual>
        <origin
            xyz="0 0 0"
            rpy="0 0 0" />
        <geometry>
            <mesh
            filename="package://project_model/meshes/Vakuumgreifer.STL" />
        </geometry>
        <material
            name="">
            <color
            rgba="0.79216 0.81961 0.93333 1" />
        </material>
        </visual>
        <collision>
        <origin
            xyz="0 0 0"
            rpy="0 0 0" />
        <geometry>
            <mesh
            filename="package://project_model/meshes/Vakuumgreifer.STL" />
        </geometry>
        </collision>
    </link>
    <joint name="Joint1" type="revolute">
        <origin xyz="0.046461 0.014071 0.12658" rpy="0 0 -3.1126" />
        <parent link="base_link" />
        <child link="Link1" />
        <axis xyz="0 0 1" />
        <limit lower="-3.1416" upper="3.1416" effort="1000.0" velocity="0.5" />
        <dynamics damping="0.2" friction="0.4" />
    </joint>
    <joint name="Joint2" type="revolute">
        <origin xyz="-0.34871 0 0.25746" rpy="1.5708 1.077 3.1416" />
        <parent link="Link1" />
        <child link="Link2" />
        <axis xyz="0 0 1" />
        <limit lower="-1.0" upper="0.8" effort="1000.0" velocity="0.25" />
        <dynamics damping="5.0" friction="2.0" />
    </joint>
    <joint name="Joint3" type="revolute">
        <origin xyz="-1.0358 -0.6058 0.465" rpy="0 0 0" />
        <parent link="Link2" />
        <child link="Link3" />
        <axis xyz="0 0 1" />
        <limit lower="-2" upper="2" effort="1000.0" velocity="0.5" />
        <dynamics damping="0.1" friction="0.2" />
    </joint>
    <joint name="Joint4" type="revolute">
        <origin xyz="-0.0435 1.21 -0.025" rpy="0 0 1.5708" />
        <parent link="Link3" />
        <child link="Link4" />
        <axis xyz="0 0 1" />
        <limit lower="-3" upper="3" effort="100.0" velocity="0.1" />
        <dynamics damping="0.1" friction="0.2" />
    </joint>
    <joint
        name="Joint_Vakuumgreifer"
        type="revolute">
        <origin
        xyz="0.28437 0.0023885 0.0039722"
        rpy="2.4444 -0.63915 0.46331" />
        <parent
        link="Link4" />
        <child
        link="Vakuumgreifer" />
        <axis
        xyz="0 1 0" />
        <limit lower="-3" upper="3" effort="100.0" velocity="0.1" />
        <dynamics damping="0.1" friction="0.2" />
    </joint>
    <gazebo>
        <plugin name="gazebo_ros_control" filename="libgazebo_ros_control.so">
            <robotNamespace>/robshift</robotNamespace>
        </plugin>
    </gazebo>
    <transmission name="transmission_Joint1">
        <type>transmission_interface/SimpleTransmission</type>
        <joint name="Joint1">
            <hardwareInterface>EffortJointInterface</hardwareInterface>
        </joint>
        <actuator name="motor_Joint1">
            <hardwareInterface>EffortJointInterface</hardwareInterface>
            <mechanicalReduction>1</mechanicalReduction>
        </actuator>
    </transmission>
    <transmission name="transmission_Joint2">
        <type>transmission_interface/SimpleTransmission</type>
        <joint name="Joint2">
            <hardwareInterface>EffortJointInterface</hardwareInterface>
        </joint>
        <actuator name="motor_Joint2">
            <hardwareInterface>EffortJointInterface</hardwareInterface>
            <mechanicalReduction>1</mechanicalReduction>
        </actuator>
    </transmission>
    <transmission name="transmission_Joint3">
        <type>transmission_interface/SimpleTransmission</type>
        <joint name="Joint3">
            <hardwareInterface>EffortJointInterface</hardwareInterface>
        </joint>
        <actuator name="motor_Joint3">
            <hardwareInterface>EffortJointInterface</hardwareInterface>
            <mechanicalReduction>1</mechanicalReduction>
        </actuator>
    </transmission>
    <transmission name="transmission_Joint4">
        <type>transmission_interface/SimpleTransmission</type>
        <joint name="Joint4">
            <hardwareInterface>EffortJointInterface</hardwareInterface>
        </joint>
        <actuator name="motor_Joint4">
            <hardwareInterface>EffortJointInterface</hardwareInterface>
            <mechanicalReduction>1</mechanicalReduction>
        </actuator>
    </transmission>
    <transmission name="transmission_Joint_Vakuumgreifer">
        <type>transmission_interface/SimpleTransmission</type>
        <joint name="Joint_Vakuumgreifer">
            <hardwareInterface>EffortJointInterface</hardwareInterface>
        </joint>
        <actuator name="motor_Joint_Vakuumgreifer">
            <hardwareInterface>EffortJointInterface</hardwareInterface>
            <mechanicalReduction>1</mechanicalReduction>
        </actuator>
    </transmission>
</robot>

